2024-11-06 16:08:35.046 | INFO     | __main__:main:72 - 正在初始化机器人...
2024-11-06 16:08:35.048 | INFO     | src.robot.flexiv:__init__:22 - 正在连接Flexiv机器人 192.168.2.110...
2024-11-06 16:08:35.655 | INFO     | src.robot.flexiv:__init__:26 - 正在使能机器人...
2024-11-06 16:08:35.681 | INFO     | src.robot.flexiv:__init__:28 - 机器人初始化完成
2024-11-06 16:08:35.682 | INFO     | __main__:main:79 - 正在初始化相机...
2024-11-06 16:08:36.406 | INFO     | __main__:main:86 - 正在初始化标记检测器...
2024-11-06 16:08:36.411 | INFO     | __main__:main:93 - 正在初始化手眼标定器...
2024-11-06 16:08:36.414 | ERROR    | __main__:main:124 - 程序运行出错: Error locating target 'src.calibration.HandEyeCalibrator', set env var HYDRA_FULL_ERROR=1 to see chained exception.
full_key: calibration
2024-11-06 16:08:36.415 | ERROR    | __main__:main:126 - Traceback (most recent call last):
  File "/home/yutong/anaconda3/envs/robocal/lib/python3.8/site-packages/hydra/_internal/utils.py", line 644, in _locate
    obj = getattr(obj, part)
AttributeError: module 'src' has no attribute 'calibration'

During handling of the above exception, another exception occurred:

Traceback (most recent call last):
  File "/home/yutong/anaconda3/envs/robocal/lib/python3.8/site-packages/hydra/_internal/utils.py", line 650, in _locate
    obj = import_module(mod)
  File "/home/yutong/anaconda3/envs/robocal/lib/python3.8/importlib/__init__.py", line 127, in import_module
    return _bootstrap._gcd_import(name[level:], package, level)
  File "<frozen importlib._bootstrap>", line 1014, in _gcd_import
  File "<frozen importlib._bootstrap>", line 991, in _find_and_load
  File "<frozen importlib._bootstrap>", line 975, in _find_and_load_unlocked
  File "<frozen importlib._bootstrap>", line 671, in _load_unlocked
  File "<frozen importlib._bootstrap_external>", line 843, in exec_module
  File "<frozen importlib._bootstrap>", line 219, in _call_with_frames_removed
  File "/home/yutong/OptiCalibrate/src/calibration/__init__.py", line 1, in <module>
    from .hand_eye_calibrator import HandEyeCalibrator
ModuleNotFoundError: No module named 'src.calibration.hand_eye_calibrator'

The above exception was the direct cause of the following exception:

Traceback (most recent call last):
  File "/home/yutong/anaconda3/envs/robocal/lib/python3.8/site-packages/hydra/_internal/instantiate/_instantiate2.py", line 134, in _resolve_target
    target = _locate(target)
  File "/home/yutong/anaconda3/envs/robocal/lib/python3.8/site-packages/hydra/_internal/utils.py", line 653, in _locate
    raise ImportError(
ImportError: Error loading 'src.calibration.HandEyeCalibrator':
ModuleNotFoundError("No module named 'src.calibration.hand_eye_calibrator'")
Are you sure that 'calibration' is importable from module 'src'?

The above exception was the direct cause of the following exception:

Traceback (most recent call last):
  File "/home/yutong/OptiCalibrate/main.py", line 94, in main
    calibrator = instantiate(cfg.calibration)
  File "/home/yutong/anaconda3/envs/robocal/lib/python3.8/site-packages/hydra/_internal/instantiate/_instantiate2.py", line 226, in instantiate
    return instantiate_node(
  File "/home/yutong/anaconda3/envs/robocal/lib/python3.8/site-packages/hydra/_internal/instantiate/_instantiate2.py", line 333, in instantiate_node
    _target_ = _resolve_target(node.get(_Keys.TARGET), full_key)
  File "/home/yutong/anaconda3/envs/robocal/lib/python3.8/site-packages/hydra/_internal/instantiate/_instantiate2.py", line 139, in _resolve_target
    raise InstantiationException(msg) from e
hydra.errors.InstantiationException: Error locating target 'src.calibration.HandEyeCalibrator', set env var HYDRA_FULL_ERROR=1 to see chained exception.
full_key: calibration

2024-11-06 16:08:36.429 | INFO     | __main__:main:130 - 程序已终止
2024-11-06 16:08:36.429 | INFO     | src.robot.flexiv:__del__:55 - 正在关闭机器人连接...
