2024-11-06 16:23:34.652 | INFO     | __main__:main:73 - 正在初始化机器人...
2024-11-06 16:23:34.655 | INFO     | src.robot.flexiv:__init__:22 - 正在连接Flexiv机器人 192.168.2.110...
2024-11-06 16:23:35.258 | INFO     | src.robot.flexiv:__init__:26 - 正在使能机器人...
2024-11-06 16:23:35.283 | INFO     | src.robot.flexiv:__init__:28 - 机器人初始化完成
2024-11-06 16:23:35.284 | INFO     | __main__:main:80 - 正在初始化相机...
2024-11-06 16:23:35.820 | INFO     | __main__:main:87 - 正在初始化标记检测器...
2024-11-06 16:23:35.823 | INFO     | __main__:main:94 - 正在初始化手眼标定器...
2024-11-06 16:23:35.825 | DEBUG    | __main__:main:96 - Calibration config: _target_: src.calibration.hand_eye_calibrator.HandEyeCalibrator
method: eye_in_hand
calib_method: CALIB_HAND_EYE_TSAI
output_path: calibrations/eye_in_hand_result.json
min_samples: 10
max_samples: 30
min_angle_diff: 15.0
min_distance_diff: 0.1
max_rep_error: 2.0
position_limits:
  x:
  - -0.5
  - 0.5
  'y':
  - -0.5
  - 0.5
  z:
  - 0.3
  - 0.8
angle_limits:
  rx:
  - -30
  - 30
  ry:
  - -30
  - 30
  rz:
  - -30
  - 30
validation:
  enabled: true
  num_test_poses: 5
  max_position_error: 0.01
  max_angle_error: 1.0

2024-11-06 16:23:35.833 | ERROR    | __main__:main:131 - 程序运行出错: Error in call to target 'src.calibration.hand_eye_calibrator.HandEyeCalibrator':
TypeError("__init__() got an unexpected keyword argument 'calib_method'")
full_key: calibration
2024-11-06 16:23:35.833 | ERROR    | __main__:main:133 - Traceback (most recent call last):
  File "/home/yutong/anaconda3/envs/robocal/lib/python3.8/site-packages/hydra/_internal/instantiate/_instantiate2.py", line 92, in _call_target
    return _target_(*args, **kwargs)
TypeError: __init__() got an unexpected keyword argument 'calib_method'

The above exception was the direct cause of the following exception:

Traceback (most recent call last):
  File "/home/yutong/OptiCalibrate/main.py", line 98, in main
    calibrator = instantiate(
  File "/home/yutong/anaconda3/envs/robocal/lib/python3.8/site-packages/hydra/_internal/instantiate/_instantiate2.py", line 226, in instantiate
    return instantiate_node(
  File "/home/yutong/anaconda3/envs/robocal/lib/python3.8/site-packages/hydra/_internal/instantiate/_instantiate2.py", line 347, in instantiate_node
    return _call_target(_target_, partial, args, kwargs, full_key)
  File "/home/yutong/anaconda3/envs/robocal/lib/python3.8/site-packages/hydra/_internal/instantiate/_instantiate2.py", line 97, in _call_target
    raise InstantiationException(msg) from e
hydra.errors.InstantiationException: Error in call to target 'src.calibration.hand_eye_calibrator.HandEyeCalibrator':
TypeError("__init__() got an unexpected keyword argument 'calib_method'")
full_key: calibration

2024-11-06 16:23:35.844 | INFO     | __main__:main:137 - 程序已终止
2024-11-06 16:23:35.844 | INFO     | src.robot.flexiv:__del__:55 - 正在关闭机器人连接...
